Workbook
Name AccumulatorStatuses: INDIRECT({"Accumulator!$I$8","Accumulator!$P$8","Accumulator!$V$8","Accumulator!$AC$8","Accumulator!$Z$52","Accumulator!$Q$52","Accumulator!$H$52","Accumulator!$F$58"})
Name BattCellCapacity: Datasheets!$D$5
Name BattCellMaxV: Datasheets!$D$6
Name BattCellNomV: Datasheets!$D$7
Name BusCap: PrechargeDischarge!$D$10
Name CellsPerTempSensor: Accumulator!$Q$25
Name ConductorNames: Datasheets!$A$19:$A$37
Name ConductorsTable: Datasheets!$A$19:$I$37
Name ConnectorNames: Datasheets!$A$73:$A$91
Name ConnectorsTable: Datasheets!$A$73:$F$91
Name ContactorNames: Datasheets!$A$65:$A$69
Name ContactorsTable: Datasheets!$A$65:$G$69
Name DischargeRes: PrechargeDischarge!$J$6
Name ErrorText: "WARNING"
Name FuseNames: Datasheets!$A$41:$A$52
Name FusesTable: Datasheets!$A$41:$G$52
Name FusibleLink_Current1: Accumulator!#REF!
Name FusibleLink_Current10: Accumulator!#REF!
Name FusibleLink_Current11: Accumulator!#REF!
Name FusibleLink_Current12: Accumulator!#REF!
Name FusibleLink_Current13: Accumulator!#REF!
Name FusibleLink_Current14: Accumulator!#REF!
Name FusibleLink_Current15: Accumulator!#REF!
Name FusibleLink_Current16: Accumulator!#REF!
Name FusibleLink_Current2: Accumulator!#REF!
Name FusibleLink_Current3: Accumulator!#REF!
Name FusibleLink_Current4: Accumulator!#REF!
Name FusibleLink_Current5: Accumulator!#REF!
Name FusibleLink_Current6: Accumulator!#REF!
Name FusibleLink_Current7: Accumulator!#REF!
Name FusibleLink_Current8: Accumulator!#REF!
Name FusibleLink_Current9: Accumulator!#REF!
Name FusibleLink_Time1: Accumulator!#REF!
Name FusibleLink_Time10: Accumulator!#REF!
Name FusibleLink_Time11: Accumulator!#REF!
Name FusibleLink_Time12: Accumulator!#REF!
Name FusibleLink_Time13: Accumulator!#REF!
Name FusibleLink_Time14: Accumulator!#REF!
Name FusibleLink_Time15: Accumulator!#REF!
Name FusibleLink_Time16: Accumulator!#REF!
Name FusibleLink_Time2: Accumulator!#REF!
Name FusibleLink_Time3: Accumulator!#REF!
Name FusibleLink_Time4: Accumulator!#REF!
Name FusibleLink_Time5: Accumulator!#REF!
Name FusibleLink_Time6: Accumulator!#REF!
Name FusibleLink_Time7: Accumulator!#REF!
Name FusibleLink_Time8: Accumulator!#REF!
Name FusibleLink_Time9: Accumulator!#REF!
Name IncompleteText: "BLANK"
Name InsulationNames: Datasheets!$A$95:$A$104
Name InsulationsTable: Datasheets!$A$95:$H$104
Name MaxTSVoltage: Accumulator!$G$4
Name NominalTSVoltage: Accumulator!$G$5
Name NumAccum: Accumulator!$G$3
Name OKText: "OK"
Name PrechargeRes: PrechargeDischarge!$D$6
Name ResistorsNames: Datasheets!$A$56:$A$61
Name ResistorsTable: Datasheets!$A$56:$J$61
Name TotalCells: Accumulator!$G$6

Sheet Overview
A1: Instructions | J1: Status
A2: Input Cells: Cells that require user input have an orange background. Status Indicators: Cells, sections, and worksheets each have an overall status, indicated by blue background cells. Images and Schematics: For sections requiring images or schematics, paste the image over the specified area. Use high-resolution images to allow for zooming if needed, and then resize the image appropriately. Datasheets: Provide a hyperlink to the manufacturer's datasheet where requested. Additional Comments: Sections labeled "Additional Comments" are provided for documenting anything the team feels is not adequately covered in the specified fields. Completing these sections is optional. | J2: Datasheets | L2: =Datasheets!C1 -> OK
J3: TS Schematics | L3: ='TS Schematics'!B1 -> OK
J4: Accumulator | L4: =Accumulator!B1 -> OK
J5: Precharge/Discharge | L5: =PrechargeDischarge!B1 -> OK
J6: Charging | L6: =Charging!B1 -> OK
J7: Shutdown Circuit | L7: ='Shutdown Circuit'!B1 -> BLANK
J8: Torque Security | L8: ='Torque Security'!$B$1 -> OK
J9: Other | L9: =Other!B1 -> BLANK
J11: Team Name | L11: NU Racing
J12: University | L12: University of Newcastle
J13: Competition Year | L13: 2025
J15: Max TS Voltage | L15: =MaxTSVoltage -> 453.6 | M15: V
J16: Accumulator Fuse | L16: =Accumulator!W20 -> 100 | M16: A
A19: Additional Comments
A38: Template Revision History
A39: Version | B39: Date | C39: Comment
A40: 2.4 | B40: 45565 | C40: Updated for 2025 rules and terminology, general bug fixes.
A41: 2.3 | B41: 45228 | C41: Updated for 2024 season.
A42: 2.2 | B42: 44868 | C42: Updated for 2023 season.
A43: 2.1 | B43: 44491 | C43: Updated for 2022 season.
A44: 2.0 | B44: 44162 | C44: Multiple updates and bug fixes.

Sheet Datasheets
B1: Status | C1: {=IF( SUM(COUNTIF(INDIRECT({"Datasheets!$F$2","Datasheets!$K$17","Datasheets!$K$39","Datasheets!$N$54","Datasheets!$K$63","Datasheets!$J$71","Datasheets!$L$93"}), "="&IncompleteText))>0, IncompleteText, IF(SUM(COUNTIF(INDIRECT({"Datasheets!$F$2","Datasheets!$K$17","Datasheets!$K$39","Datasheets!$N$54","Datasheets!$K$63","Datasheets!$J$71","Datasheets!$L$93"}), "="&ErrorText)), ErrorText, OKText))} -> OK
B2: Battery Cell | F2: =IF(COUNTBLANK(D3:D14)>0, IncompleteText, OKText) -> OK
B3: Make | D3: Sony Murata
B4: Model | D4: VTC6
B5: Nominal Capacity | D5: 3.1 | E5: Ahr
B6: Maximum Voltage | D6: 4.2 | E6: V
B7: Nominal Voltage | D7: 3.6 | E7: V
B8: Minimum Voltage | D8: 2.5 | E8: V
B9: Max output current | D9: 45 | E9: A
B10: Max continuous current | D10: 30 | E10: A
B11: Max Cell temp | D11: 60 | E11: C
B12: Cell Chemistry | D12: LiPO4
B13: Datasheet | D13: https://enepaq.com/wp-content/uploads/2025/02/Datasheet_with_VTC6_rev_D2024-10-28-1.pdf
B14: SDS | D14: https://enepaq.com/wp-content/uploads/2025/02/Datasheet_with_VTC6_rev_D2024-10-28-1.pdf
B15: Additional Comments | D15: Cells are assembled in Energus li1x6pvtc6t packs
B17: Conductors | K17: =IF(COUNTIF(K19:K37, "="&IncompleteText), IncompleteText, IF(COUNTIF(K19:K37, "="&ErrorText), ErrorText, OKText)) -> OK
B18: Manufacturer | C18: Part Number | D18: Size [mm2] | E18: Voltage [V] | F18: Ampacity [A] | G18: Max Temp [C] | H18: Datasheet | J18: Location Used | L18: Additional Comments | Q18: Rules References
A19: =CONCATENATE(INDIRECT(CONCATENATE("B",ROW(A19))), " ", INDIRECT(CONCATENATE("C",ROW(A19)))) -> LAPP 3806143 | B19: LAPP | C19: 3806143 | D19: 25 | E19: 600 | F19: 136 | G19: 110 | H19: https://lappaustralia.com.au/downloads/LAPP/LAPP%20AUS%20-%20SDI%20R-E-110%20LSZH%20-%20Tinned%20Switchboard%20Flex%20-%20Datasheet.pdf | J19: Accumulator to HIP | K19: =IF(COUNTBLANK(B19:J19)=9,IncompleteText,IF(AND(COUNTBLANK(B19:J19)=1, G19>=90),OKText,ErrorText)) -> OK | L19: Used between Accumulator and HIP | Q19: EV.5.2.1 EV.5.2.5 EV.6.3 EV.6.3.2 EV.6.6.4
A20: =CONCATENATE(INDIRECT(CONCATENATE("B",ROW(A20))), " ", INDIRECT(CONCATENATE("C",ROW(A20)))) -> LAPP 3806142 | B20: LAPP | C20: 3806142 | D20: 16 | E20: 600 | F20: 102 | G20: 110 | H20: https://lappaustralia.com.au/downloads/LAPP/LAPP%20AUS%20-%20SDI%20R-E-110%20LSZH%20-%20Tinned%20Switchboard%20Flex%20-%20Datasheet.pdf | J20: Accumulator | K20: =IF(COUNTBLANK(B20:J20)=9,"",IF(AND(COUNTBLANK(B20:J20)=1, G20>=90),OKText,ErrorText)) -> OK | L20: Used for short distances in the Accumulator
A21: =CONCATENATE(INDIRECT(CONCATENATE("B",ROW(A21))), " ", INDIRECT(CONCATENATE("C",ROW(A21)))) -> LAPP 16001303 | B21: LAPP | C21: 16001303 | D21: 4 | E21: 750 | F21: 23 | G21: 110 | H21: https://lappaustralia.com.au/files/attachments/LAPP/CAT2018_2019/LAPP-Main-Catalogue-2018-19%20_%2087.pdf | J21: Charger | K21: =IF(COUNTBLANK(B21:J21)=9,"",IF(AND(COUNTBLANK(B21:J21)=1, G21>=90),OKText,ErrorText)) -> OK | L21: 5 core length used between 3 phase outlet and charger input
A22: =CONCATENATE(INDIRECT(CONCATENATE("B",ROW(A22))), " ", INDIRECT(CONCATENATE("C",ROW(A22)))) -> ELECTRA SRCV3025E | B22: ELECTRA | C22: SRCV3025E | D22: 2.5 | E22: 750 | F22: 21 | G22: 110 | H22: https://cdn.shopify.com/s/files/1/0108/9116/5777/files/SRCV.pdf?v=1754739559 | J22: Charger | K22: =IF(COUNTBLANK(B22:J22)=9,"",IF(AND(COUNTBLANK(B22:J22)=1, G22>=90),OKText,ErrorText)) -> OK | L22: 4 core, used within charger to connect power supplies
A23: =CONCATENATE(INDIRECT(CONCATENATE("B",ROW(A23))), " ", INDIRECT(CONCATENATE("C",ROW(A23)))) -> ELECTRA SRCV2025E | B23: ELECTRA | C23: SRCV2025E | D23: 2.5 | E23: 750 | F23: 22 | G23: 110 | H23: https://cdn.shopify.com/s/files/1/0108/9116/5777/files/SRCV.pdf?v=1754739559 | J23: Charger | K23: =IF(COUNTBLANK(B23:J23)=9,"",IF(AND(COUNTBLANK(B23:J23)=1, G23>=90),OKText,ErrorText)) -> OK | L23: DC, used within charger to connect Phase to Phase DC supply
A24: =CONCATENATE(INDIRECT(CONCATENATE("B",ROW(A24))), " ", INDIRECT(CONCATENATE("C",ROW(A24)))) -> HELUKABEL 29468 | B24: HELUKABEL | C24: 29468 | D24: 1.5 | E24: 550 | F24: 16 | G24: 110 | H24: https://assets-cdn.helukabel.com/suppliers/Helukabel/documents/db/1DB_29450_en.pdf | J24: Charger | K24: =IF(COUNTBLANK(B24:J24)=9,"",IF(AND(COUNTBLANK(B24:J24)=1, G24>=90),OKText,ErrorText)) -> OK | L24: Used as Active, Neutral and Earth power outlet connections
A25: =CONCATENATE(INDIRECT(CONCATENATE("B",ROW(A25))), " ", INDIRECT(CONCATENATE("C",ROW(A25)))) -> ELETECK E254881 | B25: ELETECK | C25: E254881 | D25: 0.33 | E25: 600 | F25: 5 | G25: 105 | H25: https://docs.rs-online.com/7294/0900766b815851f3.pdf | J25: Accumulator and HIP | K25: =IF(COUNTBLANK(B25:J25)=9,"",IF(AND(COUNTBLANK(B25:J25)=1, G25>=90),OKText,ErrorText)) -> OK | L25: Used as auxilary wire when nessecery for HV, Such as Precharge, Discharge, etc
A26: =CONCATENATE(INDIRECT(CONCATENATE("B",ROW(A26))), " ", INDIRECT(CONCATENATE("C",ROW(A26)))) -> EXRAD EXRAD-XHV/XLE-50 | B26: EXRAD | C26: EXRAD-XHV/XLE-50 | D26: 50 | E26: 1000 | F26: 218 | G26: 150 | H26: https://www.champcable.com/wp-content/uploads/2018/08/212.-SAE-EXRAD-150-HVFX-XLE-Shielded-Battery-Cable.pdf | J26: HIP to Motor Controller | K26: =IF(COUNTBLANK(B26:J26)=9,"",IF(AND(COUNTBLANK(B26:J26)=1, G26>=90),OKText,ErrorText)) -> OK | L26: Supplied by Cascadia as per of the Motor Controller as it has speciality connectors.
A27: =CONCATENATE(INDIRECT(CONCATENATE("B",ROW(A27))), " ", INDIRECT(CONCATENATE("C",ROW(A27)))) -> EXRAD EXRAD-XHV/XLE-50 | B27: EXRAD | C27: EXRAD-XHV/XLE-50 | D27: 50 | E27: 600 | F27: 218 | G27: 150 | H27: https://www.champcable.com/wp-content/uploads/2018/08/212.-SAE-EXRAD-150-HVFX-XLE-Shielded-Battery-Cable.pdf | J27: Motor Controller to Motor | K27: =IF(COUNTBLANK(B27:J27)=9,"",IF(AND(COUNTBLANK(B27:J27)=1, G27>=90),OKText,ErrorText)) -> OK | L27: Supplied by Cascadia as per of the Motor Controller as it has speciality connectors.
A28: =CONCATENATE(INDIRECT(CONCATENATE("B",ROW(A28))), " ", INDIRECT(CONCATENATE("C",ROW(A28)))) | K28: =IF(COUNTBLANK(B28:J28)=9,"",IF(AND(COUNTBLANK(B28:J28)=1, G28>=90),OKText,ErrorText))
A29: =CONCATENATE(INDIRECT(CONCATENATE("B",ROW(A29))), " ", INDIRECT(CONCATENATE("C",ROW(A29)))) | K29: =IF(COUNTBLANK(B29:J29)=9,"",IF(AND(COUNTBLANK(B29:J29)=1, G29>=90),OKText,ErrorText))
A30: =CONCATENATE(INDIRECT(CONCATENATE("B",ROW(A30))), " ", INDIRECT(CONCATENATE("C",ROW(A30)))) | K30: =IF(COUNTBLANK(B30:J30)=9,"",IF(AND(COUNTBLANK(B30:J30)=1, G30>=90),OKText,ErrorText))
A31: =CONCATENATE(INDIRECT(CONCATENATE("B",ROW(A31))), " ", INDIRECT(CONCATENATE("C",ROW(A31)))) | K31: =IF(COUNTBLANK(B31:J31)=9,"",IF(AND(COUNTBLANK(B31:J31)=1, G31>=90),OKText,ErrorText))
A32: =CONCATENATE(INDIRECT(CONCATENATE("B",ROW(A32))), " ", INDIRECT(CONCATENATE("C",ROW(A32)))) | K32: =IF(COUNTBLANK(B32:J32)=9,"",IF(AND(COUNTBLANK(B32:J32)=1, G32>=90),OKText,ErrorText))
A33: =CONCATENATE(INDIRECT(CONCATENATE("B",ROW(A33))), " ", INDIRECT(CONCATENATE("C",ROW(A33)))) | K33: =IF(COUNTBLANK(B33:J33)=9,"",IF(AND(COUNTBLANK(B33:J33)=1, G33>=90),OKText,ErrorText))
A34: =CONCATENATE(INDIRECT(CONCATENATE("B",ROW(A34))), " ", INDIRECT(CONCATENATE("C",ROW(A34)))) | K34: =IF(COUNTBLANK(B34:J34)=9,"",IF(AND(COUNTBLANK(B34:J34)=1, G34>=90),OKText,ErrorText))
A35: =CONCATENATE(INDIRECT(CONCATENATE("B",ROW(A35))), " ", INDIRECT(CONCATENATE("C",ROW(A35)))) | K35: =IF(COUNTBLANK(B35:J35)=9,"",IF(AND(COUNTBLANK(B35:J35)=1, G35>=90),OKText,ErrorText))
A36: =CONCATENATE(INDIRECT(CONCATENATE("B",ROW(A36))), " ", INDIRECT(CONCATENATE("C",ROW(A36)))) | K36: =IF(COUNTBLANK(B36:J36)=9,"",IF(AND(COUNTBLANK(B36:J36)=1, G36>=90),OKText,ErrorText))
A37: =CONCATENATE(INDIRECT(CONCATENATE("B",ROW(A37))), " ", INDIRECT(CONCATENATE("C",ROW(A37)))) | K37: =IF(COUNTBLANK(B37:J37)=9,"",IF(AND(COUNTBLANK(B37:J37)=1, G37>=90),OKText,ErrorText))
A38: =CONCATENATE(INDIRECT(CONCATENATE("B",ROW(A38))), " ", INDIRECT(CONCATENATE("C",ROW(A38))))
A39: =CONCATENATE(INDIRECT(CONCATENATE("B",ROW(A39))), " ", INDIRECT(CONCATENATE("C",ROW(A39)))) -> Fuses | B39: Fuses | K39: =IF(COUNTIF(K41:K52, "="&IncompleteText), IncompleteText, IF(COUNTIF(K41:K52, "="&ErrorText), ErrorText, OKText)) -> OK
A40: =CONCATENATE(INDIRECT(CONCATENATE("B",ROW(A40))), " ", INDIRECT(CONCATENATE("C",ROW(A40)))) -> Manufacturer Part Number | B40: Manufacturer | C40: Part Number | D40: Voltage [V] | E40: AC/DC | F40: Current [A] | G40: Interrupt [A] | H40: Datasheet | J40: Location Used | L40: Additional Comments | Q40: Rules References
A41: =CONCATENATE(INDIRECT(CONCATENATE("B",ROW(A41))), " ", INDIRECT(CONCATENATE("C",ROW(A41)))) -> Littlefuse L50QS100.T | B41: Littlefuse | C41: L50QS100.T | D41: 500 | E41: DC | F41: 100 | G41: 50000 | H41: https://au.mouser.com/datasheet/2/240/L50QS_High_Speed_Fuse_Datasheet-3311429.pdf | J41: Top Plate | K41: =IF(COUNTBLANK(B41:J41)=9,IncompleteText,IF(COUNTBLANK(B41:J41)=1,OKText,ErrorText)) -> OK | L41: Main fuse in accumulator | Q41: EV.5.2.1 EV.6.6
...

Sheet TS Schematics
A1: Status | B1: {=IF(SUM(COUNTIF(INDIRECT({"'TS Schematics'!$K$28","'TS Schematics'!$W$28","'TS Schematics'!$K$46"}), "="&IncompleteText)), IncompleteText, IF(SUM(COUNTIF(INDIRECT({"'TS Schematics'!$K$28","'TS Schematics'!$W$28","'TS Schematics'!$K$46"}), "="&ErrorText)), ErrorText, OKText))} -> OK
A2: Tractive System Schematic | M2: Accumulator TS Schematic | Y2: Additional Comments
Y3: Each of the 9 accumulator segments are comprised of 12 li1x6pvtc6t packs arranged in series. These li1x6pvtc6t packs consist of 6 inidivdual Sony Murata 18650 cells arranged in parallel.
A28: Vehicle Tractive System Schematic Shows | K28: =IF(COUNTIF(K30:K43, "="&IncompleteText), IncompleteText, IF(COUNTIF(K30:K43, "="&ErrorText), ErrorText, OKText)) -> OK | M28: Accumulator TS Schematic Shows | W28: =IF(COUNTIF(W30:W41, "="&IncompleteText), IncompleteText, IF(COUNTIF(W30:W41, "="&ErrorText), ErrorText, OKText)) -> OK
A29: Rules References | M29: Rules References
C30: Shows details of all TS circuits outside of accumulator | J30: TRUE | K30: =IF(ISBLANK(J30),IncompleteText, IF(J30, OKText, ErrorText)) -> OK | O30: Details of all TS circuits within accumulator | V30: TRUE | W30: =IF(ISBLANK(V30),IncompleteText, IF(V30, OKText, ErrorText)) -> OK
C31: Accumulator is shown as a single element (without internal details) | J31: TRUE | K31: =IF(ISBLANK(J31),IncompleteText, IF(J31, OKText, ErrorText)) -> OK | O31: All wire gauges labeled | V31: TRUE | W31: =IF(ISBLANK(V31),IncompleteText, IF(V31, OKText, ErrorText)) -> OK
C32: All wire gauges labeled | J32: TRUE | K32: =IF(ISBLANK(J32),IncompleteText, IF(J32, OKText, ErrorText)) -> OK | O32: All fuses labeled with ampacity | V32: TRUE | W32: =IF(ISBLANK(V32),IncompleteText, IF(V32, OKText, ErrorText)) -> OK
C33: All fuses labeled with ampacity | J33: TRUE | K33: =IF(ISBLANK(J33),IncompleteText, IF(J33, OKText, ErrorText)) -> OK | M33: EV.6.6.6 | O33: All wires > 150mm have a fuse within the first 150mm from the source | V33: TRUE | W33: =IF(ISBLANK(V33),IncompleteText, IF(V33, OKText, ErrorText)) -> OK
A34: EV.6.6.6 | C34: All wires > 150mm have a fuse within the first 150mm from the source | J34: TRUE | K34: =IF(ISBLANK(J34),IncompleteText, IF(J34, OKText, ErrorText)) -> OK | O34: Fuse locations represent physical location | V34: TRUE | W34: =IF(ISBLANK(V34),IncompleteText, IF(V34, OKText, ErrorText)) -> OK
C35: Fuse locations represent physical location | J35: TRUE | K35: =IF(ISBLANK(J35),IncompleteText, IF(J35, OKText, ErrorText)) -> OK | O35: Connectors labeled with Make/Model | V35: TRUE | W35: =IF(ISBLANK(V35),IncompleteText, IF(V35, OKText, ErrorText)) -> OK
C36: Enclosures shown | J36: TRUE | K36: =IF(ISBLANK(J36),IncompleteText, IF(J36, OKText, ErrorText)) -> OK | O36: Standard schematic symbols used | V36: TRUE | W36: =IF(ISBLANK(V36),IncompleteText, IF(V36, OKText, ErrorText)) -> OK
C37: Connectors labeled with Make/Model | J37: TRUE | K37: =IF(ISBLANK(J37),IncompleteText, IF(J37, OKText, ErrorText)) -> OK | O37: All text is readable (zooming is allowed) | V37: TRUE | W37: =IF(ISBLANK(V37),IncompleteText, IF(V37, OKText, ErrorText)) -> OK
C38: Standard schematic symbols used | J38: TRUE | K38: =IF(ISBLANK(J38),IncompleteText, IF(J38, OKText, ErrorText)) -> OK | M38: EV.5.4 | O38: IRs | V38: TRUE | W38: =IF(ISBLANK(V38),IncompleteText, IF(V38, OKText, ErrorText)) -> OK
C39: All text is readable (zooming is allowed) | J39: TRUE | K39: =IF(ISBLANK(J39),IncompleteText, IF(J39, OKText, ErrorText)) -> OK | M39: EV.5.3 | O39: Maintenance plugs | V39: TRUE | W39: =IF(ISBLANK(V39),IncompleteText, IF(V39, OKText, ErrorText)) -> OK
A40: EV.5.8 | C40: TSMPs | J40: TRUE | K40: =IF(ISBLANK(J40),IncompleteText, IF(J40, OKText, ErrorText)) -> OK | O40: Cells (details of all intercell connections may be abstracted) | V40: TRUE | W40: =IF(ISBLANK(V40),IncompleteText, IF(V40, OKText, ErrorText)) -> OK
C41: Motor Controller | J41: TRUE | K41: =IF(ISBLANK(J41),IncompleteText, IF(J41, OKText, ErrorText)) -> OK | M41: EV.5.7 | O41: Accumulator Indicator (must be powered directly by TS) | V41: TRUE | W41: =IF(ISBLANK(V41),IncompleteText, IF(V41, OKText, ErrorText)) -> OK
C42: Motor | J42: TRUE | K42: =IF(ISBLANK(J42),IncompleteText, IF(J42, OKText, ErrorText)) -> OK
A43: EV.5.8.5 | C43: TSMPs not fused | J43: TRUE | K43: =IF(ISBLANK(J43),IncompleteText, IF(J43, OKText, ErrorText)) -> OK
A46: Must be shown on at least one schematic | K46: =IF(COUNTIF(K48:K54, "="&IncompleteText), IncompleteText, IF(COUNTIF(K48:K54, "="&ErrorText), ErrorText, OKText)) -> OK
A47: Rules References
A48: EV.7.6 | C48: IMD | J48: TRUE | K48: =IF(ISBLANK(J48),IncompleteText, IF(J48, OKText, ErrorText)) -> OK
A49: EV.5.5 | C49: MSD | J49: TRUE | K49: =IF(ISBLANK(J49),IncompleteText, IF(J49, OKText, ErrorText)) -> OK
A50: EV.5.6 | C50: Precharge | J50: TRUE | K50: =IF(ISBLANK(J50),IncompleteText, IF(J50, OKText, ErrorText)) -> OK
A51: EV.5.6 | C51: Discharge | J51: TRUE | K51: =IF(ISBLANK(J51),IncompleteText, IF(J51, OKText, ErrorText)) -> OK
A52: EV.3.2; EV.5.1.3 | C52: Energy Meter (shunt and TS sense connection) | J52: TRUE | K52: =IF(ISBLANK(J52),IncompleteText, IF(J52, OKText, ErrorText)) -> OK
A53: EV.5.6.3.b | C53: Discharge still functions when MSD is opened | J53: TRUE | K53: =IF(ISBLANK(J53),IncompleteText, IF(J53, OKText, ErrorText)) -> OK
A54: EV.5.6.3.c | C54: Discharge is not fused | J54: TRUE | K54: =IF(ISBLANK(J54),IncompleteText, IF(J54, OKText, ErrorText)) -> OK

Sheet Accumulator
A1: Status | B1: {=IF(SUM(COUNTIF(INDIRECT({"Accumulator!$I$3","Accumulator!$I$4","Accumulator!$L$8","Accumulator!$S$8","Accumulator!$Y$8","Accumulator!$AF$8","Accumulator!$AB$52","Accumulator!$S$52","Accumulator!$J$52","Accumulator!$H$62","Accumulator!$AK$52","Accumulator!$AT$52","Accumulator!$BC$52"}), "="&IncompleteText)), IncompleteText, IF(SUM(COUNTIF(INDIRECT({"Accumulator!$I$3","Accumulator!$I$4","Accumulator!$L$8","Accumulator!$S$8","Accumulator!$Y$8","Accumulator!$AF$8","Accumulator!$AB$52","Accumulator!$S$52","Accumulator!$J$52","Accumulator!$H$62","Accumulator!$AK$52","Accumulator!$AT$52","Accumulator!$BC$52"}), "="&ErrorText)), ErrorText, OKText))} -> OK
A3: Segment-to-Segment Connection | G3: Series | I3: =IF(ISBLANK(G3), IncompleteText, OKText) -> OK
A4: Maximum TS Voltage | G4: {=IF(G3="Series",SUM(C12:C29)*BattCellMaxV,C12*BattCellMaxV*SUM(IF(FREQUENCY(G12:G29,G12:G29)>0,1)))} -> 453.6 | H4: V | I4: =IF(G4 > 600, ErrorText, OKText) -> OK
A5: Nominal TS Voltage | G5: {=IF(G3="Series",SUM(C12:C29)*BattCellNomV,C12*BattCellNomV*SUM(IF(FREQUENCY(G12:G29,G12:G29)>0,1)))} -> 388.8 | H5: V
A6: Total Cells | G6: =SUMPRODUCT(B12:B29,C12:C29) -> 648
A8: Segment Data | L8: =IF(COUNTIF(L9:L29, "="&IncompleteText), IncompleteText, IF(COUNTIF(L9:L29, "="&ErrorText), ErrorText, OKText)) -> OK | M8: BMS | S8: =IF(COUNTIF(S9:S30, "="&IncompleteText), IncompleteText, IF(COUNTIF(S9:S30, "="&ErrorText), ErrorText, OKText)) -> OK | T8: Maintenance Plugs | Y8: =IF(COUNTIF(Y9:Y24, "="&IncompleteText), IncompleteText, IF(COUNTIF(Y9:Y24, "="&ErrorText), ErrorText, OKText)) -> OK | Z8: Insulating Materials | AF8: =IF(COUNTIF(AF9:AF19, "="&IncompleteText), IncompleteText, IF(COUNTIF(AF9:AF19, "="&ErrorText), ErrorText, OKText)) -> OK | AG8: Additional Comments
A9: Cell Connection Order | F9: Parallel then Series | L9: =IF(ISBLANK(F9), IncompleteText, OKText) -> OK | M9: BMS Type | Q9: Centralized | S9: =IF(ISBLANK(Q9), IncompleteText, OKText) -> OK | T9: Connector | W9: Methode EBC 5.7mm | Y9: =IF(ISBLANK(W9), IncompleteText, OKText) -> OK | Z9: Between cells and accum. container | AD9: RS PRO 20305179 | AF9: =IF(ISBLANK(AD9), IncompleteText, OKText) -> OK | AG9: Due to design of temperature monitoring PCB the centre 2 battery packs in each segment will not have temperature monitored.
A10: Segment | B10: Parallel cells | C10: Series cells | F10: Temp Sensors | G10: Accumulator Number | H10: Max Voltage [V] | J10: Segment Energy [MJ] | M10: BMS Source | Q10: Purchased | S10: =IF(ISBLANK(Q10), IncompleteText, OKText) -> OK | T10: Ampacity | W10: =VLOOKUP(W9, ConnectorsTable, 5, FALSE) -> 320 | X10: A | Y10: =IF(ISERROR(W10),IncompleteText,IF(G3="Series",IF(W10>=W20,OKText,ErrorText),IF(G3="Parallel",IF(W10>=W12,OKText,ErrorText),IncompleteText))) -> OK | Z10: Voltage Rating | AD10: =VLOOKUP(AD9, InsulationsTable, 6, FALSE) -> 31500 | AE10: V | AF10: =IF(ISERROR(AD10), IncompleteText, IF(AD10 < MaxTSVoltage, ErrorText, OKText)) -> OK
M11: Make | N11: Ewert Energy | P11: Model | Q11: Orion 2 | S11: =IF(Q10="Purchased", IF(OR(ISBLANK(N11), ISBLANK(Q11)), IncompleteText, OKText), "") -> OK | T11: Segment Fuse | Y11: =IF(G3="Series","",IF(ISBLANK(W11), IncompleteText, OKText)) | Z11: Temperature Rating | AD11: =VLOOKUP(AD9, InsulationsTable, 7, FALSE) -> 130 | AE11: C | AF11: =IF(ISERROR(AD11), IncompleteText, IF(AD11 < 90, ErrorText, OKText)) -> OK
A12: 1 | B12: 6 | C12: 12 | F12: 20 | G12: 1 | H12: =C12*BattCellMaxV -> 50.4 | J12: =H12*B12*BattCellCapacity*0.0036 -> 3.374784 | L12: =IF(COUNTBLANK(B12:C12)+COUNTBLANK(F12:G12) > 0, IncompleteText, IF(OR(H12>120, J12>6), ErrorText, OKText)) -> OK | M12: Galvanic Isolation TS to GLV | Q12: 1500 | R12: V | S12: =IF(ISBLANK(Q12), IncompleteText, IF(Q12<G4, ErrorText, OKText)) -> OK | T12: Segment Fuse Ampacity | W12: =VLOOKUP(W11, FusesTable, 6, FALSE) -> #N/A | X12: A | Z12: Flammability Rating | AD12: =VLOOKUP(AD9, InsulationsTable, 8, FALSE) -> UL94 V-0
A13: 2 | B13: 6 | C13: 12 | F13: 20 | G13: 1 | H13: =C13*BattCellMaxV -> 50.4 | J13: =H13*B13*BattCellCapacity*0.0036 -> 3.374784 | L13: =IF(COUNTBLANK(B13:C13)+COUNTBLANK(F13:G13)=4,"",IF(COUNTBLANK(B13:C13)+COUNTBLANK(F13:G13) > 0, IncompleteText, IF(OR(H13>120, J13>6), ErrorText, OKText))) -> OK | M13: Galvanic Isolation between segments | Q13: 2500 | R13: V | S13: =IF(ISBLANK(Q13), IncompleteText, IF(Q13<MAX(H12:I29), ErrorText, OKText)) -> OK | T13: IR | Z13: On top of cells | AD13: PCB KB6165F TG 149 | AF13: =IF(ISBLANK(AD13), IncompleteText, OKText) -> OK
A14: 3 | B14: 6 | C14: 12 | F14: 20 | G14: 1 | H14: =C14*BattCellMaxV -> 50.4 | J14: =H14*B14*BattCellCapacity*0.0036 -> 3.374784 | L14: =IF(COUNTBLANK(B14:C14)+COUNTBLANK(F14:G14)=4,"",IF(COUNTBLANK(B14:C14)+COUNTBLANK(F14:G14) > 0, IncompleteText, IF(OR(H14>120, J14>6), ErrorText, OKText))) -> OK | M14: Galvanic Isolation device | S14: =IF($Q$10="Team Built", IF(ISBLANK(Q14), IncompleteText, OKText), "") | T14: Make/Model | W14: GigaVac EPICGX | Y14: =IF(ISBLANK(W14), IncompleteText, OKText) -> OK | Z14: Voltage Rating | AD14: =VLOOKUP(AD13, InsulationsTable, 6, FALSE) -> 40000 | AE14: V | AF14: =IF(ISERROR(AD14), IncompleteText, IF(AD14 < MaxTSVoltage, ErrorText, OKText)) -> OK
A15: 4 | B15: 6 | C15: 12 | F15: 20 | G15: 1 | H15: =C15*BattCellMaxV -> 50.4 | J15: =H15*B15*BattCellCapacity*0.0036 -> 3.374784 | L15: =IF(COUNTBLANK(B15:C15)+COUNTBLANK(F15:G15)=4,"",IF(COUNTBLANK(B15:C15)+COUNTBLANK(F15:G15) > 0, IncompleteText, IF(OR(H15>120, J15>6), ErrorText, OKText))) -> OK | M15: Gavlanic Isolation device datasheet | S15: =IF($Q$10="Team Built", IF(ISBLANK(Q15), IncompleteText, OKText), "") | T15: Contact Voltage Rating | W15: =VLOOKUP(W14, ContactorsTable, 4, FALSE) -> 800 | X15: V | Y15: =IF(ISERROR(W15), IncompleteText, IF(W15 < MaxTSVoltage, ErrorText, OKText)) -> OK | Z15: Temperature Rating | AD15: =VLOOKUP(AD13, InsulationsTable, 7, FALSE) -> 170 | AE15: C | AF15: =IF(ISERROR(AD15), IncompleteText, IF(AD15 < 90, ErrorText, OKText)) -> OK
A16: 5 | B16: 6 | C16: 12 | F16: 20 | G16: 1 | H16: =C16*BattCellMaxV -> 50.4 | J16: =H16*B16*BattCellCapacity*0.0036 -> 3.374784 | L16: =IF(COUNTBLANK(B16:C16)+COUNTBLANK(F16:G16)=4,"",IF(COUNTBLANK(B16:C16)+COUNTBLANK(F16:G16) > 0, IncompleteText, IF(OR(H16>120, J16>6), ErrorText, OKText))) -> OK | M16: Voltage Sense Leads | T16: Max switching current | W16: =VLOOKUP(W14, ContactorsTable, 6, FALSE) -> 500 | X16: A | Z16: Flammability Rating | AD16: =VLOOKUP(AD13, InsulationsTable, 8, FALSE) -> UL94 V-1
A17: 6 | B17: 6 | C17: 12 | F17: 20 | G17: 1 | H17: =C17*BattCellMaxV -> 50.4 | J17: =H17*B17*BattCellCapacity*0.0036 -> 3.374784 | L17: =IF(COUNTBLANK(B17:C17)+COUNTBLANK(F17:G17)=4,"",IF(COUNTBLANK(B17:C17)+COUNTBLANK(F17:G17) > 0, IncompleteText, IF(OR(H17>120, J17>6), ErrorText, OKText))) -> OK | M17: Maximum Unfused Lead Length | Q17: 16 | R17: mm | S17: =IF(ISBLANK(Q17), IncompleteText, IF(Q17>150, ErrorText, OKText)) -> OK | T17: Max continuous current | W17: =VLOOKUP(W14, ContactorsTable, 5, FALSE) -> 225 | X17: A | Y17: =IF(ISERROR(W17), IncompleteText, IF(W17>=W20, OKText, ErrorText)) -> OK | Z17: Separating IRs and Fuse from cells | AD17: ePOL PEEK-NAT/BLK | AF17: =IF(ISBLANK(AD17), IncompleteText, OKText) -> OK
A18: 7 | B18: 6 | C18: 12 | F18: 20 | G18: 1 | H18: =C18*BattCellMaxV -> 50.4 | J18: =H18*B18*BattCellCapacity*0.0036 -> 3.374784 | L18: =IF(COUNTBLANK(B18:C18)+COUNTBLANK(F18:G18)=4,"",IF(COUNTBLANK(B18:C18)+COUNTBLANK(F18:G18) > 0, IncompleteText, IF(OR(H18>120, J18>6), ErrorText, OKText))) -> OK | M18: Sense Lead Overcurrent Protection Device | Q18: Bel Fuse C1Q 1 | S18: =IF(ISBLANK(Q18), IncompleteText, OKText) -> OK | T18: Main Fuse | Z18: Voltage Rating | AD18: =VLOOKUP(AD17, InsulationsTable, 6, FALSE) -> 240000 | AE18: V | AF18: =IF(ISERROR(AD18), IncompleteText, IF(AD18 < MaxTSVoltage, ErrorText, OKText)) -> OK
A19: 8 | B19: 6 | C19: 12 | F19: 20 | G19: 1 | H19: =C19*BattCellMaxV -> 50.4 | J19: =H19*B19*BattCellCapacity*0.0036 -> 3.374784 | L19: =IF(COUNTBLANK(B19:C19)+COUNTBLANK(F19:G19)=4,"",IF(COUNTBLANK(B19:C19)+COUNTBLANK(F19:G19) > 0, IncompleteText, IF(OR(H19>120, J19>6), ErrorText, OKText))) -> OK | M19: Overcurrent Location | Q19: Other | S19: =IF(ISBLANK(Q19), IncompleteText, OKText) -> OK | T19: Main Fuse | W19: Littlefuse L50QS100.T | Y19: =IF(ISBLANK(W19), IncompleteText, OKText) -> OK | Z19: Temperature Rating | AD19: =VLOOKUP(AD17, InsulationsTable, 7, FALSE) -> 340 | AE19: C | AF19: =IF(ISERROR(AD19), IncompleteText, IF(AD19 < 90, ErrorText, OKText)) -> OK
A20: 9 | B20: 6 | C20: 12 | F20: 20 | G20: 1 | H20: =C20*BattCellMaxV -> 50.4 | J20: =H20*B20*BattCellCapacity*0.0036 -> 3.374784 | L20: =IF(COUNTBLANK(B20:C20)+COUNTBLANK(F20:G20)=4,"",IF(COUNTBLANK(B20:C20)+COUNTBLANK(F20:G20) > 0, IncompleteText, IF(OR(H20>120, J20>6), ErrorText, OKText))) -> OK | M20: Overcurrent Other Location | Q20: CANaMon | S20: =IF(Q19="Other", IF(ISBLANK(Q20), IncompleteText, OKText), "") -> OK | T20: Main fuse ampacity | W20: =VLOOKUP(W19, FusesTable, 6, FALSE) -> 100 | X20: A | Z20: Flammability Rating | AD20: =VLOOKUP(AD17, InsulationsTable, 8, FALSE) -> UL94 V-0
A21: 10 | H21: =C21*BattCellMaxV -> 0 | J21: =H21*B21*BattCellCapacity*0.0036 -> 0 | L21: =IF(COUNTBLANK(B21:C21)+COUNTBLANK(F21:G21)=4,"",IF(COUNTBLANK(B21:C21)+COUNTBLANK(F21:G21) > 0, IncompleteText, IF(OR(H21>120, J21>6), ErrorText, OKText))) | M21: Overcurrent Voltage Rating | Q21: =VLOOKUP(Q18, FusesTable, 4, FALSE) -> 63 | R21: V | S21: =IF(ISERROR(Q21), IncompleteText, IF(AND(Q21 < MAX(H12:I29), Q9 = "Centralized"), ErrorText, OKText)) -> OK | T21: Main fuse voltage | W21: =VLOOKUP(W19, FusesTable, 4, FALSE) -> 500 | X21: V | Y21: =IF(ISERROR(W21), IncompleteText,IF(W21 < MaxTSVoltage, ErrorText, OKText)) -> OK
A22: 11 | H22: =C22*BattCellMaxV -> 0 | J22: =H22*B22*BattCellCapacity*0.0036 -> 0 | L22: =IF(COUNTBLANK(B22:C22)+COUNTBLANK(F22:G22)=4,"",IF(COUNTBLANK(B22:C22)+COUNTBLANK(F22:G22) > 0, IncompleteText, IF(OR(H22>120, J22>6), ErrorText, OKText))) | M22: Temperature Sensors | T22: MSD
A23: 12 | H23: =C23*BattCellMaxV -> 0 | J23: =H23*B23*BattCellCapacity*0.0036 -> 0 | L23: =IF(COUNTBLANK(B23:C23)+COUNTBLANK(F23:G23)=4,"",IF(COUNTBLANK(B23:C23)+COUNTBLANK(F23:G23) > 0, IncompleteText, IF(OR(H23>120, J23>6), ErrorText, OKText))) | M23: Temp Sensor Location | Q23: On cell terminal | S23: =IF(ISBLANK(Q23), IncompleteText, OKText) -> OK | T23: MSD | W23: Hirose Electric Group EM30MSD(04) | Y23: =IF(ISBLANK(W23), IncompleteText, OKText) -> OK
A24: 13 | H24: =C24*BattCellMaxV -> 0 | J24: =H24*B24*BattCellCapacity*0.0036 -> 0 | L24: =IF(COUNTBLANK(B24:C24)+COUNTBLANK(F24:G24)=4,"",IF(COUNTBLANK(B24:C24)+COUNTBLANK(F24:G24) > 0, IncompleteText, IF(OR(H24>120, J24>6), ErrorText, OKText))) | M24: Distance to cell terminal | Q24: 8 | R24: mm | S24: =IF(Q23="On cell terminal","",IF(ISBLANK(Q24),IncompleteText,IF(Q24<10,OKText,ErrorText))) | T24: Ampacity | W24: =VLOOKUP(W23, ConnectorsTable, 5, FALSE) -> 200 | X24: A | Y24: =IF(ISERROR(W24), IncompleteText, IF(W24 < W20, ErrorText, OKText)) -> OK
A25: 14 | H25: =C25*BattCellMaxV -> 0 | J25: =H25*B25*BattCellCapacity*0.0036 -> 0 | L25: =IF(COUNTBLANK(B25:C25)+COUNTBLANK(F25:G25)=4,"",IF(COUNTBLANK(B25:C25)+COUNTBLANK(F25:G25) > 0, IncompleteText, IF(OR(H25>120, J25>6), ErrorText, OKText))) | M25: Cells sensed per sensor | Q25: 2 | R25: cells | S25: =IF(ISBLANK(Q25), IncompleteText, OKText) -> OK
A26: 15 | H26: =C26*BattCellMaxV -> 0 | J26: =H26*B26*BattCellCapacity*0.0036 -> 0 | L26: =IF(COUNTBLANK(B26:C26)+COUNTBLANK(F26:G26)=4,"",IF(COUNTBLANK(B26:C26)+COUNTBLANK(F26:G26) > 0, IncompleteText, IF(OR(H26>120, J26>6), ErrorText, OKText))) | M26: Thermal Contact material used
A27: 16 | H27: =C27*BattCellMaxV -> 0 | J27: =H27*B27*BattCellCapacity*0.0036 -> 0 | L27: =IF(COUNTBLANK(B27:C27)+COUNTBLANK(F27:G27)=4,"",IF(COUNTBLANK(B27:C27)+COUNTBLANK(F27:G27) > 0, IncompleteText, IF(OR(H27>120, J27>6), ErrorText, OKText))) | M27: Thermal contact material datasheet | S27: =IF(ISBLANK($Q$26), "", IF(ISBLANK(Q27), IncompleteText, OKText))
A28: 17 | H28: =C28*BattCellMaxV -> 0 | J28: =H28*B28*BattCellCapacity*0.0036 -> 0 | L28: =IF(COUNTBLANK(B28:C28)+COUNTBLANK(F28:G28)=4,"",IF(COUNTBLANK(B28:C28)+COUNTBLANK(F28:G28) > 0, IncompleteText, IF(OR(H28>120, J28>6), ErrorText, OKText))) | M28: Thermal contact material conductivity | R28: W/(m∙K) | S28: =IF(ISBLANK($Q$26), "", IF(ISBLANK(Q28), IncompleteText, OKText))
A29: 18 | H29: =C29*BattCellMaxV -> 0 | J29: =H29*B29*BattCellCapacity*0.0036 -> 0 | L29: =IF(COUNTBLANK(B29:C29)+COUNTBLANK(F29:G29)=4,"",IF(COUNTBLANK(B29:C29)+COUNTBLANK(F29:G29) > 0, IncompleteText, IF(OR(H29>120, J29>6), ErrorText, OKText))) | M29: Thermal contact material thickness | R29: mm | S29: =IF(ISBLANK($Q$26), "", IF(ISBLANK(Q29), IncompleteText, OKText))
M30: Percent of cells sensed | Q30: =SUMIF(L12:L29, "=OK", F12:F29)*CellsPerTempSensor/TotalCells*100 -> 55.555556 | R30: % | S30: =IF(ISERROR(Q30),IncompleteText,IF(Q30<20,ErrorText,OKText)) -> OK
A33: Picture of Maintenance Plugs | L33: Picture of Cell Connections | U33: Picture of Temperature Sensor Location | AD33: Picture of Fuse and IRs Separation from Cells | AM33: Picture of Segment Insulation between Cell Terminals and Sides of Accumulator Container | AV33: Picture of Insulation on Top of Segment
A52: Maintenance Plug(s) Picture Shows | J52: =IF(COUNTIF(J53:J56, "="&IncompleteText), IncompleteText, IF(COUNTIF(J53:J56, "="&ErrorText), ErrorText, OKText)) -> OK | L52: Cell Connections Picture Shows | S52: =IF(COUNTIF(S53:S55, "="&IncompleteText), IncompleteText, IF(COUNTIF(S53:S55, "="&ErrorText), ErrorText, OKText)) -> OK | U52: Temperature Sensor Picture Shows | AB52: =IF(COUNTIF(AB53:AB54, "="&IncompleteText), IncompleteText, IF(COUNTIF(AB53:AB54, "="&ErrorText), ErrorText, OKText)) -> OK | AD52: Fuse and IRs Separation Picture Shows | AK52: =IF(COUNTIF(AK53, "="&IncompleteText), IncompleteText, IF(COUNTIF(AK53, "="&ErrorText), ErrorText, OKText)) -> OK | AM52: Segment Insulation Picture Shows | AT52: =IF(COUNTIF(AT53, "="&IncompleteText), IncompleteText, IF(COUNTIF(AT53, "="&ErrorText), ErrorText, OKText)) -> OK | AV52: Segment Insulation Picture Shows | BC52: =IF(COUNTIF(BC53, "="&IncompleteText), IncompleteText, IF(COUNTIF(BC53, "="&ErrorText), ErrorText, OKText)) -> OK
A53: Unique Configuration of plugs | I53: TRUE | J53: =IF(ISBLANK(I53),IncompleteText, IF(I53, OKText, ErrorText)) -> OK | L53: Bolted connections have positive locking | R53: TRUE | S53: =IF(ISBLANK(R53),IncompleteText, IF(R53, OKText, ErrorText)) -> OK | U53: Temp sensor in direct contact with terminal or busbar | AA53: TRUE | AB53: =IF(ISBLANK(AA53),IncompleteText, IF(AA53, OKText, ErrorText)) -> OK | AD53: Fuse and IRs are separated from cells | AJ53: TRUE | AK53: =IF(ISBLANK(AJ53),IncompleteText, IF(AJ53, OKText, ErrorText)) -> OK | AM53: Insulation between cells and accumulator container | AS53: TRUE | AT53: =IF(ISBLANK(AS53),IncompleteText, IF(AS53, OKText, ErrorText)) -> OK | AV53: Insulation on top of cells (air not acceptable) | BB53: TRUE | BC53: =IF(ISBLANK(BB53),IncompleteText, IF(BB53, OKText, ErrorText)) -> OK
A54: Non-conductive on un-necessary surface | I54: TRUE | J54: =IF(ISBLANK(I54),IncompleteText, IF(I54, OKText, ErrorText)) -> OK | L54: Location of parallel cell overcurrent for parallel cells | R54: TRUE | S54: =IF($B$12=1,OKText,IF(ISBLANK(R54),IncompleteText, IF(R54, OKText, ErrorText))) -> OK | U54: Distance from sensor to cell negative terminal connection | AA54: TRUE | AB54: =IF(ISBLANK(AA54),IncompleteText, IF(AA54, OKText, ErrorText)) -> OK | AD54: Additional Comments | AK54: Rules References | AM54: Additional Comments | AT54: Rules References | AV54: Additional Comments | BC54: Rules References
A55: Accessible without any additional accumulator disassembly | I55: TRUE | J55: =IF(ISBLANK(I55),IncompleteText, IF(I55, OKText, ErrorText)) -> OK | L55: BMS voltage sense fuse location | R55: TRUE | S55: =IF(ISBLANK(R55),IncompleteText, IF(R55, OKText, ErrorText)) -> OK | U55: Additional Comments | AB55: Rules References | AK55: EV.5.4.4 | AT55: EV.5.2.2.a EV.5.2.3 | BC55: EV.5.2.2.a EV.5.2.3
A56: Positive Locking | I56: TRUE | J56: =IF(ISBLANK(I56),IncompleteText, IF(I56, OKText, ErrorText)) -> OK | L56: Additional Comments | S56: Rules References | U56: Please note that the li1x6pvtc6t packs used in our accumulator are configured in a 1x6 pack, not a 4x2 as pictured above. This image was taken from the pack's data sheet which covers a range of battery configurations. The locations of the sensors is the same for both configurations. | AB56: EV.7.5
A57: Additional Comments | J57: Rules References | S57: EV.6.4.1 EV.6.4.3 EV.7.4.4.a
A58: Busbar positively locked by accumulator lid. | J58: EV.5.3
A62: Parallel Cell Fusing | H62: =IF(B12=1, OKText, IF(COUNTIF(H63:H72, "="&IncompleteText), IncompleteText, IF(COUNTIF(H63:H72, "="&ErrorText), ErrorText, OKText))) -> OK | I62: Rules Referenes
A63: Source | F63: Purchased | H63: =IF(B12 <> 1, IF(ISBLANK(F63),IncompleteText,OKText), "") -> OK | I63: EV.6.6.3 EV.6.6.5
A64: Make/Model | F64: Energus Internal | H64: =IF(F63 = "Purchased", IF(ISBLANK(F64), IncompleteText, OKText), "") -> OK
A65: Continuous Current | F65: =VLOOKUP(F64, FusesTable, 6, FALSE) -> 270 | G65: A | H65: =IF(F63="Purchased", _xlfn.IFNA(IF(F65*B12/3 >= W20, OKText, ErrorText),IncompleteText), "") -> OK
...

Sheet PrechargeDischarge
A1: Status | B1: {=IF(SUM(COUNTIF(INDIRECT({"PrechargeDischarge!$F$2","PrechargeDischarge!$L$2","PrechargeDischarge!$R$2","PrechargeDischarge!$R$10"}), "="&IncompleteText)), IncompleteText, IF(SUM(COUNTIF(INDIRECT({"PrechargeDischarge!$F$2","PrechargeDischarge!$L$2","PrechargeDischarge!$R$2","PrechargeDischarge!$R$10"}), "="&ErrorText)), ErrorText, OKText))} -> OK
A2: Precharge | F2: =IF(COUNTIF(F3:F22, "="&IncompleteText), IncompleteText, IF(COUNTIF(F3:F22, "="&ErrorText), ErrorText, OKText)) -> OK | G2: Discharge | L2: =IF(COUNTIF(L3:L16, "="&IncompleteText), IncompleteText, IF(COUNTIF(L3:L16, "="&ErrorText), ErrorText, OKText)) -> OK | M2: Vehicle TSMP | R2: =IF(COUNTIF(R3:R8, "="&IncompleteText), IncompleteText, IF(COUNTIF(R3:R8, "="&ErrorText), ErrorText, OKText)) -> OK | S2: Rules References
A3: Resistor | D3: Arcol HS25 560R J | F3: =IF(ISBLANK(D3), IncompleteText, OKText) -> OK | G3: Resistor | J3: Riedon PF2472-3K3F1 | L3: =IF(ISBLANK(J3), IncompleteText, OKText) -> OK | M3: Resistor | P3: Te Connectivity SMF515KFT | R3: =IF(ISBLANK(P3), IncompleteText, OKText) -> OK | S3: EV.5.8.4
A4: # parallel | D4: 1 | F4: =IF(ISBLANK(D4), IncompleteText, OKText) -> OK | G4: # parallel | J4: 1 | L4: =IF(ISBLANK(J4), IncompleteText, OKText) -> OK | M4: # parallel | P4: 1 | R4: =IF(ISBLANK(P4), IncompleteText, OKText) -> OK
A5: # series | D5: 1 | F5: =IF(ISBLANK(D5), IncompleteText, OKText) -> OK | G5: # series | J5: 1 | L5: =IF(ISBLANK(J5), IncompleteText, OKText) -> OK | M5: # series | P5: 1 | R5: =IF(ISBLANK(P5), IncompleteText, OKText) -> OK
A6: Resistance | D6: =VLOOKUP(D3, ResistorsTable, 5, )*D5/D4 -> 560 | E6: Ohms | G6: Resistance | J6: =VLOOKUP(J3, ResistorsTable, 5, )*J5/J4 -> 3300 | K6: Ohms | M6: Resistance | P6: =VLOOKUP(P3, ResistorsTable, 5, )*P5/P4 -> 15000 | Q6: Ohms | R6: =IF(MaxTSVoltage<=200,IF(P6=5000, OKText, ErrorText),IF(MaxTSVoltage > 400, IF(P6=15000, OKText, ErrorText), IF(P6=10000, OKText, ErrorText))) -> OK
A7: Cont power | D7: =VLOOKUP(D3, ResistorsTable, 6, FALSE)*D4*D5 -> 25 | E7: W | G7: Cont power | J7: =VLOOKUP(J3, ResistorsTable, 6, FALSE)*J4*J5 -> 100 | K7: W | M7: Cont power | P7: =VLOOKUP(P3, ResistorsTable, 6, FALSE)*P5*P4 -> 5 | Q7: W | R7: =IF(P7<(MaxTSVoltage/2)^2/P6, ErrorText, OKText) -> OK
A8: power @15 sec | D8: =VLOOKUP(D3, ResistorsTable, 7, FALSE)*D4*D5 -> 75 | E8: W | G8: power @15 sec | J8: =VLOOKUP(J3, ResistorsTable, 7, FALSE)*J4*J5 -> 500 | K8: W | L8: =IF(J8<MaxTSVoltage^2/DischargeRes, ErrorText, OKText) -> OK | M8: Voltage | P8: =VLOOKUP(P3, ResistorsTable, 4, FALSE)*P5 -> 500 | Q8: V | R8: =IF(P8<(MaxTSVoltage/2), ErrorText, OKText) -> OK
A9: Voltage | D9: =VLOOKUP(D3, ResistorsTable, 4, FALSE)*D5 -> 550 | E9: V | F9: =IF(D9<MaxTSVoltage, ErrorText, OKText) -> OK | G9: Voltage | J9: =VLOOKUP(J3, ResistorsTable, 4, FALSE)*J5 -> 700 | K9: V | L9: =IF(J9<MaxTSVoltage, ErrorText, OKText) -> OK
A10: Bus Capacitance | D10: 0.65 | E10: mF | F10: =IF(ISBLANK(BusCap), IncompleteText, OKText) -> OK | G10: Peak power | J10: =MaxTSVoltage^2/DischargeRes -> 62.349382 | K10: W | M10: Charger TSMP | R10: =IF(COUNTIF(R11:R17, "="&IncompleteText), IncompleteText, IF(COUNTIF(R11:R17, "="&ErrorText), ErrorText, OKText)) -> OK | S10: Rules References
A11: End of precharge | D11: Ratio | F11: =IF(ISBLANK(D11), IncompleteText, OKText) -> OK | G11: Peak current | J11: =MaxTSVoltage/DischargeRes -> 0.13745455 | K11: A | M11: Same parts as vehicle TSMP? | P11: Yes | R11: =IF(ISBLANK(P11), IncompleteText, OKText) -> OK | S11: EV.5.8.4
G12: Discharge time (to 60V) | J12: =-LN(60/MaxTSVoltage)*DischargeRes*(BusCap/1000) -> 4.3390587 | K12: s | L12: =IF(J12>5, ErrorText, OKText) -> OK | M12: Resistor | R12: =IF(P$11="No",IF(ISBLANK(P12), IncompleteText, OKText),"")
A13: delta V | E13: V | F13: =IF(D11<>"Delta Voltage", "", IF(ISBLANK(D13), IncompleteText, IF(D13 > MaxTSVoltage*0.1, ErrorText, OKText))) | G13: Relay | J13: Cynergy DBT71210 | L13: =IF(ISBLANK(J13), IncompleteText, OKText) -> OK | M13: # parallel | R13: =IF(P$11="No",IF(ISBLANK(P13), IncompleteText, OKText),"")
A14: ending ratio | D14: 90 | E14: % | F14: =IF(D11<>"Ratio", "", IF(ISBLANK(D14), IncompleteText, IF(D14 < 90, ErrorText, OKText))) -> OK | G14: Relay voltage rating | J14: =VLOOKUP(J13, ContactorsTable, 4, FALSE) -> 7000 | K14: V | L14: =IF(J14<MaxTSVoltage, ErrorText, OKText) -> OK | M14: # series | R14: =IF(P$11="No",IF(ISBLANK(P14), IncompleteText, OKText),"")
A15: Peak power | D15: =MaxTSVoltage^2/PrechargeRes -> 367.416 | E15: W | G15: Relay current rating | J15: =VLOOKUP(J13, ContactorsTable, 5, FALSE) -> 2 | K15: A | L15: =IF(J15<J11, ErrorText, OKText) -> OK | M15: Resistance | P15: =VLOOKUP(P12, ResistorsTable, 5, )*P14/P13 -> #N/A | Q15: Ohms | R15: =IF(P$11="No",IF(MaxTSVoltage<=200,IF(P15=5000, OKText, ErrorText),IF(MaxTSVoltage > 400, IF(P15=15000, OKText, ErrorText), IF(P15=10000, OKText, ErrorText))),"")
A16: Peak current | D16: =MaxTSVoltage/PrechargeRes -> 0.81 | E16: A | G16: Normal State | J16: =VLOOKUP(J13, ContactorsTable, 7, FALSE) -> NC | L16: =IF(J16<> "NC", ErrorText, OKText) -> OK | M16: Cont power | P16: =VLOOKUP(P12, ResistorsTable, 6, FALSE)*P14*P13 -> #N/A | Q16: W | R16: =IF(P$11="No",IF(P16<(MaxTSVoltage/2)^2/P15, ErrorText, OKText),"")
A17: time to 90% | D17: =-LN(0.1)*(BusCap/1000)*PrechargeRes -> 0.83814097 | E17: sec | G17: Rules References | M17: Voltage | P17: =VLOOKUP(P12, ResistorsTable, 4, FALSE)*P14 -> #N/A | Q17: V | R17: =IF(P$11="No",IF(P17<(MaxTSVoltage/2), ErrorText, OKText),"")
A18: Precharge Res Energy to 90% | D18: =MaxTSVoltage^2*(BusCap/1000)/2*(1-EXP(-D17*2/(PrechargeRes*(BusCap/1000)))) -> 66.201015 | E18: J | G18: EV.5.6; EV.7.2.2.c
A19: Average Power | D19: =D18/D17 -> 78.985537 | E19: W
A20: Relay | D20: Omron G7L-2A-X-L | F20: =IF(ISBLANK(D20), IncompleteText, OKText) -> OK
A21: Relay voltage rating | D21: =VLOOKUP(D20, ContactorsTable, 4, FALSE) -> 1000 | E21: V | F21: =IF(D21<MaxTSVoltage, ErrorText, OKText) -> OK
A22: Relay current rating | D22: =VLOOKUP(D20, ContactorsTable, 5, FALSE) -> 20 | E22: A | F22: =IF(D22<D16, ErrorText, OKText) -> OK
A24: Additional Comments

Sheet Charging
A1: Status | B1: {=IF(SUM(COUNTIF(INDIRECT({"Charging!$F$2","Charging!$H$32","Charging!$Q$32"}), "="&IncompleteText)), IncompleteText, IF(SUM(COUNTIF(INDIRECT({"Charging!$F$2","Charging!$H$32","Charging!$Q$32"}), "="&ErrorText)), ErrorText, OKText))} -> OK
A2: Charger | F2: =IF(COUNTIF(F3:F11, "="&IncompleteText), IncompleteText, IF(COUNTIF(F3:F11, "="&ErrorText), ErrorText, OKText)) -> OK | H2: Additional Comments
A3: Make | D3: Magna Power | F3: =IF(ISBLANK(D3), IncompleteText, OKText) -> OK
A4: Model | D4: SL series | F4: =IF(ISBLANK(D4), IncompleteText, OKText) -> OK
A5: Datasheet | D5: https://magna-power.com/assets/files/datasheets/datasheet_sl_4.5.0.pdf | F5: =IF(ISBLANK(D5), IncompleteText, OKText) -> OK
A6: Input Voltage | D6: 380/400 | E6: V | F6: =IF(ISBLANK(D6), IncompleteText, OKText) -> OK
A7: Input Current | D7: 11 | E7: A | F7: =IF(ISBLANK(D7), IncompleteText, OKText) -> OK
A8: Output Voltage | D8: 500 | E8: V | F8: =IF(ISBLANK(D8), IncompleteText, OKText) -> OK
A9: Output Current | D9: 10 | E9: A | F9: =IF(ISBLANK(D9), IncompleteText, OKText) -> OK
A10: Power | D10: 4 | E10: kW | F10: =IF(ISBLANK(D10), IncompleteText, OKText) -> OK
A11: Input to Output isolation | D11: 2.5 | F11: =IF(ISBLANK(D11), IncompleteText, OKText) -> OK
A13: Charging Tractive System Schematic | J13: Charging Shutdown Circuit
A32: Charging Tractive System Schematic Shows | H32: =IF(COUNTIF(H34:H39, "="&IncompleteText), IncompleteText, IF(COUNTIF(H34:H39, "="&ErrorText), ErrorText, OKText)) -> OK | J32: Charging Shutdown Circuit Shows | Q32: =IF(COUNTIF(Q34:Q39, "="&IncompleteText), IncompleteText, IF(COUNTIF(Q34:Q39, "="&ErrorText), ErrorText, OKText)) -> OK
A33: Rules References | J33: Rules References
A34: EV.6.6 | C34: Fuse | G34: TRUE | H34: =IF(ISBLANK(G34),IncompleteText, IF(G34, OKText, ErrorText)) -> OK | J34: EV.8.3 | L34: IMD Control and Powerstage | P34: TRUE | Q34: =IF(ISBLANK(P34),IncompleteText, IF(P34, OKText, ErrorText)) -> OK
C35: Connectors | G35: TRUE | H35: =IF(ISBLANK(G35),IncompleteText, IF(G35, OKText, ErrorText)) -> OK | J35: EV.8.3 | L35: AMS | P35: TRUE | Q35: =IF(ISBLANK(P35),IncompleteText, IF(P35, OKText, ErrorText)) -> OK
C36: Wire Gauge | G36: TRUE | H36: =IF(ISBLANK(G36),IncompleteText, IF(G36, OKText, ErrorText)) -> OK | J36: EV.8.2.7 | L36: Charger Shutdown Button | P36: TRUE | Q36: =IF(ISBLANK(P36),IncompleteText, IF(P36, OKText, ErrorText)) -> OK
A37: EV.8.4 | C37: IMD | G37: TRUE | H37: =IF(ISBLANK(G37),IncompleteText, IF(G37, OKText, ErrorText)) -> OK | J37: EV.8.4 | L37: IRs | P37: TRUE | Q37: =IF(ISBLANK(P37),IncompleteText, IF(P37, OKText, ErrorText)) -> OK
A38: EV.8.4.2 | C38: IRs | G38: TRUE | H38: =IF(ISBLANK(G38),IncompleteText, IF(G38, OKText, ErrorText)) -> OK | J38: EV.5.9 | L38: Charge Connector Interlock | P38: TRUE | Q38: =IF(ISBLANK(P38),IncompleteText, IF(P38, OKText, ErrorText)) -> OK
A39: EV.8.2.6 | C39: TSMPs | G39: TRUE | H39: =IF(ISBLANK(G39),IncompleteText, IF(G39, OKText, ErrorText)) -> OK | J39: EV.8.2.4; EV.8.4.2.c | L39: Charge Control (CAN, Enable, etc.) | P39: TRUE | Q39: =IF(ISBLANK(P39),IncompleteText, IF(P39, OKText, ErrorText)) -> OK
A40: Additional Comments | J40: Additional Comments

Sheet Shutdown Circuit
A1: Status | B1: {=IF(SUM(COUNTIF(INDIRECT({"'Shutdown Circuit'!$F$2","'Shutdown Circuit'!$M$2","'Shutdown Circuit'!$K$36","'Shutdown Circuit'!$W$36","'Shutdown Circuit'!$W$75"}), "="&IncompleteText)), IncompleteText, IF(SUM(COUNTIF(INDIRECT({"'Shutdown Circuit'!$F$2","'Shutdown Circuit'!$M$2","'Shutdown Circuit'!$K$36","'Shutdown Circuit'!$W$36","'Shutdown Circuit'!$W$75"}), "="&ErrorText)), ErrorText, OKText))} -> BLANK
A2: IMD | F2: =IF(COUNTIF(F4:F5, "="&IncompleteText), IncompleteText, IF(COUNTIF(F4:F5, "="&ErrorText), ErrorText, OKText)) -> OK | H2: BSPD | M2: =IF(COUNTIF(M4:M8, "="&IncompleteText), IncompleteText, IF(COUNTIF(M4:M8, "="&ErrorText), ErrorText, OKText)) -> OK
A3: Rules Reference | D3: EV.7.6 | H3: Rules Reference | K3: EV.7.7
A4: Make/Model | D4: Bender IR155-3204 | F4: =IF(ISBLANK(D4), IncompleteText, OKText) -> OK | H4: Current Sensor Make/Model | K4: Tamura L31S100S05FS | M4: =IF(ISBLANK(K4), IncompleteText, OKText) -> OK
A5: Setpoint | D5: 250 | E5: kΩ | F5: =IF(ISBLANK(D5), IncompleteText, IF(D5<(MaxTSVoltage*0.5), ErrorText, OKText)) -> OK | H5: Current Sensor Datasheet | K5: https://au.mouser.com/datasheet/2/397/TCOA_S_A0010069265_1-2563810.pdf | M5: =IF(ISBLANK(K5), IncompleteText, OKText) -> OK
H6: Trip Current | K6: 12.5 | L6: A | M6: =IF(ISBLANK(K6),IncompleteText,IF(K6>(5000/NominalTSVoltage),ErrorText,OKText)) -> OK
H7: Sensor Output @ Trip Current | K7: 2.57 | L7: V | M7: =IF(ISBLANK(K7), IncompleteText, OKText) -> OK
H8: Accuracy @ Trip Current | K8: 0.1 | L8: A | M8: =IF(ISBLANK(K8), IncompleteText, OKText) -> OK
A10: Shutdown Circuit Schematic | M10: BSPD System Schematic
A36: Shutdown Circuit Schematic Shows | K36: =IF(COUNTIF(K38:K62, "="&IncompleteText), IncompleteText, IF(COUNTIF(K38:K62, "="&ErrorText), ErrorText, OKText)) -> OK | M36: BSPD System Schematic Shows | W36: =IF(COUNTIF(W38:W40, "="&IncompleteText), IncompleteText, IF(COUNTIF(W38:W40, "="&ErrorText), ErrorText, OKText)) -> OK
A37: Rules References
A38: EV.7.9.2 | C38: GLVMS | J38: TRUE | K38: =IF(ISBLANK(J38),IncompleteText, IF(J38, OKText, ErrorText)) -> OK | M38: BSPD Current Sensor input open/short circuit protection | V38: TRUE | W38: =IF(ISBLANK(V38),IncompleteText, IF(V38, OKText, ErrorText)) -> OK
A39: EV.7.9.3 | C39: TSMS | J39: TRUE | K39: =IF(ISBLANK(J39),IncompleteText, IF(J39, OKText, ErrorText)) -> OK | M39: BSPD Brake Position input open/short circuit protection | V39: TRUE | W39: =IF(ISBLANK(V39),IncompleteText, IF(V39, OKText, ErrorText)) -> OK
A40: EV.7.10.3 | C40: 2 Side Shutdown Buttons | J40: TRUE | K40: =IF(ISBLANK(J40),IncompleteText, IF(J40, OKText, ErrorText)) -> OK | M40: Shutdown circuit powerstage | V40: TRUE | W40: =IF(ISBLANK(V40),IncompleteText, IF(V40, OKText, ErrorText)) -> OK
A41: EV.7.10.4 | C41: 1 Cockpit Shutdown Button | J41: TRUE | K41: =IF(ISBLANK(J41),IncompleteText, IF(J41, OKText, ErrorText)) -> OK | M41: Additional Comments | V41: Rules References
A42: T.3.3 | C42: Brake Over Travel Switch (BOTS) | J42: TRUE | K42: =IF(ISBLANK(J42),IncompleteText, IF(J42, OKText, ErrorText)) -> OK | V42: EV.7.7
A43: T.9.4 | C43: Inertia Switch | J43: TRUE | K43: =IF(ISBLANK(J43),IncompleteText, IF(J43, OKText, ErrorText)) -> OK
A44: EV.7.3 | C44: BMS | J44: TRUE | K44: =IF(ISBLANK(J44),IncompleteText, IF(J44, OKText, ErrorText)) -> OK
A45: EV.7.6 | C45: IMD | J45: TRUE | K45: =IF(ISBLANK(J45),IncompleteText, IF(J45, OKText, ErrorText)) -> OK
A46: EV.7.7 | C46: BSPD | J46: TRUE | K46: =IF(ISBLANK(J46),IncompleteText, IF(J46, OKText, ErrorText)) -> OK
A47: EV.5.5.3 | C47: MSD Interlock | J47: TRUE | K47: =IF(ISBLANK(J47),IncompleteText, IF(J47, OKText, ErrorText)) -> OK | M47: Ready To Move Light Schematic
A48: EV.7.1.4 | C48: IMD, AMS, BSPD have independent power stages | J48: TRUE | K48: =IF(ISBLANK(J48),IncompleteText, IF(J48, OKText, ErrorText)) -> OK
A49: EV.4.1.3.a | C49: Outboard Wheel Motor Interlocks (if applicable) | J49: TRUE | K49: =IF(ISBLANK(J49),IncompleteText, IF(J49, OKText, ErrorText)) -> OK
C50: GLV Battery | J50: TRUE | K50: =IF(ISBLANK(J50),IncompleteText, IF(J50, OKText, ErrorText)) -> OK
C51: HV DC/DC converter GLV connection (if applicable) | J51: TRUE | K51: =IF(ISBLANK(J51),IncompleteText, IF(J51, OKText, ErrorText)) -> OK
A52: T.9.2.2 | C52: GLV Fuse | J52: TRUE | K52: =IF(ISBLANK(J52),IncompleteText, IF(J52, OKText, ErrorText)) -> OK
C53: Wire Gauge | J53: TRUE | K53: =IF(ISBLANK(J53),IncompleteText, IF(J53, OKText, ErrorText)) -> OK
A54: EV.7.1.2; EV.7.1.5 | C54: Precharge Contactor coil | J54: TRUE | K54: =IF(ISBLANK(J54),IncompleteText, IF(J54, OKText, ErrorText)) -> OK
A55: EV.7.1.2; EV.7.1.5 | C55: Positive IR coil | J55: TRUE | K55: =IF(ISBLANK(J55),IncompleteText, IF(J55, OKText, ErrorText)) -> OK
A56: EV.7.1.2; EV.7.1.5 | C56: Negative IR coil | J56: TRUE | K56: =IF(ISBLANK(J56),IncompleteText, IF(J56, OKText, ErrorText)) -> OK
A57: EV.5.6.3.a | C57: Discharge Contactor coil | J57: TRUE | K57: =IF(ISBLANK(J57),IncompleteText, IF(J57, OKText, ErrorText)) -> OK
A58: EV.7.9.3.b | C58: TSMS is last switch | J58: TRUE | K58: =IF(ISBLANK(J58),IncompleteText, IF(J58, OKText, ErrorText)) -> OK
A59: EV.7.9.2.a | C59: GLVMS is first switch | J59: TRUE | K59: =IF(ISBLANK(J59),IncompleteText, IF(J59, OKText, ErrorText)) -> OK
C60: Uses proper electrical schematic symbols | J60: TRUE | K60: =IF(ISBLANK(J60),IncompleteText, IF(J60, OKText, ErrorText)) -> OK
C61: Labels/text are readable (zooming in is acceptable) | J61: TRUE | K61: =IF(ISBLANK(J61),IncompleteText, IF(J61, OKText, ErrorText)) -> OK
A62: EV.5.9 | C62: Interlocks on TS connectors outside of an enclosure | J62: TRUE | K62: =IF(ISBLANK(J62),IncompleteText, IF(J62, OKText, ErrorText)) -> OK
A63: Additional Comments | J63: Rules References
J64: EV.7.1 EV.7.2
M75: Ready to Move Light Schematic Shows | W75: =IF(COUNTIF(W76:W82, "="&IncompleteText), IncompleteText, IF(COUNTIF(W76:W82, "="&ErrorText), ErrorText, OKText)) -> BLANK
M76: Light controlled by >60V present in TS (hardware-based voltage detection) | V76: TRUE | W76: =IF(ISBLANK(V76),IncompleteText, IF(V76, OKText, ErrorText)) -> OK
...

Sheet Torque Security
A1: Status | B1: =IF(SUM(COUNTIF(INDIRECT({"'Torque Security'!$F$2","'Torque Security'!$S$2"}), "="&IncompleteText)), IncompleteText, IF(SUM(COUNTIF(INDIRECT({"'Torque Security'!$F$2","'Torque Security'!$S$2"}), "="&ErrorText)), ErrorText, OKText)) -> OK
A2: APPS Sensor Transfer function | F2: =IF(COUNTIF(F5:F10, "="&IncompleteText), IncompleteText, IF(COUNTIF(F5:F10, "="&ErrorText), ErrorText, OKText)) -> OK | H2: Torque Control Path Security Checks | S2: =IF(COUNTIF(S6:S11, "="&IncompleteText), IncompleteText, IF(COUNTIF(S6:S11, "="&ErrorText), ErrorText, OKText)) -> OK
A3: Rules Reference | C3: T.4.2.3
A4: Position | B4: APPS1 Output [V] | D4: APPS2 Output [V] | H4: Source Device | J4: Destination Device | L4: Communication | M4: Redundant | N4: Out Of Range | O4: Correlation | P4: Checksum | Q4: Timeout | R4: Other | T4: Additional Comments
A5: 0 | B5: 0.372 | D5: 0.74 | F5: =IF(OR(ISBLANK(B5),ISBLANK(D5)), IncompleteText, OKText) -> OK
A6: 0.2 | B6: 0.711 | D6: 1.4 | F6: =IF(OR(ISBLANK(B6),ISBLANK(D6)),IncompleteText,IF(OR(AND(_xlfn.XOR(B6<D6,B5<D5),B5<>D5),B6=D6),ErrorText,OKText)) -> OK | H6: APPS | J6: Pedal Box ECU | L6: Analog | M6: 2 Sensors | N6: Yes | O6: No | P6: No | Q6: No | S6: =IF(COUNTBLANK(J6:L6)>1, IncompleteText, OKText) -> OK
A7: 0.4 | B7: 1.03 | D7: 2.06 | F7: =IF(OR(ISBLANK(B7),ISBLANK(D7)), IncompleteText, IF(OR(_xlfn.XOR(B7<D7,B6<D6),B7=D7), ErrorText, OKText)) -> OK | H7: =IF(ISBLANK(J6),"",J6) -> Pedal Box ECU | J7: DEN | L7: Digital | M7: No | N7: No | O7: No | P7: CAN | Q7: Yes | S7: =IF(ISBLANK(J7), "", IF(ISBLANK(L7), IncompleteText, OKText)) -> OK
A8: 0.6 | B8: 1.36 | D8: 2.71 | F8: =IF(OR(ISBLANK(B8),ISBLANK(D8)), IncompleteText, IF(OR(_xlfn.XOR(B8<D8,B7<D7),B8=D8), ErrorText, OKText)) -> OK | H8: =IF(ISBLANK(J7),"",J7) -> DEN | J8: CEN | L8: Digital | M8: No | N8: No | O8: No | P8: CAN | Q8: Yes | S8: =IF(ISBLANK(J8), "", IF(ISBLANK(L8), IncompleteText, OKText)) -> OK
A9: 0.8 | B9: 1.69 | D9: 3.36 | F9: =IF(OR(ISBLANK(B9),ISBLANK(D9)), IncompleteText, IF(OR(_xlfn.XOR(B9<D9,B8<D8),B9=D9), ErrorText, OKText)) -> OK | H9: =IF(ISBLANK(J8),"",J8) -> CEN | J9: Motor Controller | L9: Digital | M9: No | N9: No | O9: No | P9: CAN | Q9: Yes | S9: =IF(ISBLANK(J9), "", IF(ISBLANK(L9), IncompleteText, OKText)) -> OK
A10: 1 | B10: 2.05 | D10: 4.09 | F10: =IF(OR(ISBLANK(B10),ISBLANK(D10)), IncompleteText, IF(OR(_xlfn.XOR(B10<D10,B9<D9),B10=D10), ErrorText, OKText)) -> OK | H10: =IF(ISBLANK(J9),"",J9) -> Motor Controller | S10: =IF(ISBLANK(J10), "", IF(ISBLANK(L10), IncompleteText, OKText))
H11: =IF(ISBLANK(J10),"",J10) | S11: =IF(ISBLANK(J11), "", IF(ISBLANK(L11), IncompleteText, OKText))

Sheet Other
A1: Status | B1: {=IF(SUM(COUNTIF(INDIRECT({"Other!$F$2","Other!$L$2","Other!$H$28","Other!$Q$28"}), "="&IncompleteText)), IncompleteText, IF(SUM(COUNTIF(INDIRECT({"Other!$F$2","Other!$L$2","Other!$H$28","Other!$Q$28"}), "="&ErrorText)), ErrorText, OKText))} -> BLANK
A2: Motor Controller | F2: =IF(COUNTIF(F3:F7, "="&IncompleteText), IncompleteText, IF(COUNTIF(F3:F7, "="&ErrorText), ErrorText, OKText)) -> OK | G2: Motor | L2: =IF(COUNTIF(L3:L5, "="&IncompleteText), IncompleteText, IF(COUNTIF(L3:L5, "="&ErrorText), ErrorText, OKText)) -> OK
A3: Make | D3: Cascadia | F3: =IF(ISBLANK(D3), IncompleteText, OKText) -> OK | G3: Make | J3: Emrax | L3: =IF(ISBLANK(J3), IncompleteText, OKText) -> OK
A4: Model | D4: CM200DX | F4: =IF(ISBLANK(D4), IncompleteText, OKText) -> OK | G4: Model | J4: 228 MV | L4: =IF(ISBLANK(J4), IncompleteText, OKText) -> OK
A5: Datasheet | D5: https://www.cascadiamotion.com/_files/ugd/7833d4_f46965a239f843afa9a2fa82f7d5d1ed.pdf | F5: =IF(ISBLANK(D5), IncompleteText, OKText) -> OK | G5: Datasheet | J5: https://emrax.com/wp-content/uploads/2024/02/EMRAX_228_datasheet_v1.5.pdf | L5: =IF(ISBLANK(J5), IncompleteText, OKText) -> OK
A6: Galvanic Isolation between TS and control | D6: 1500 | E6: V | F6: =IF(ISBLANK(D6),IncompleteText,IF(D6<MaxTSVoltage,ErrorText,OKText)) -> OK
A9: Picture of Energy Meter download connector on car to prove compliance with EV.3.2.2 | J9: Picture of Tractive System Status Indicator on car to prove compliance with EV.5.11
A28: Energy Meter Download Picture Shows | H28: =IF(COUNTIF(H29, "="&IncompleteText), IncompleteText, IF(COUNTIF(H29, "="&ErrorText), ErrorText, OKText)) -> OK | J28: Tractive System Status Indicator Shows | Q28: =IF(COUNTIF(Q29, "="&IncompleteText), IncompleteText, IF(COUNTIF(Q29, "="&ErrorText), ErrorText, OKText)) -> BLANK
A29: Energy Meter Download Connector | G29: TRUE | H29: =IF(ISBLANK(G29),IncompleteText, IF(G29, OKText, ErrorText)) -> OK | J29: Tractive System Status Indicator placement in vehicle | Q29: =IF(ISBLANK(P29),IncompleteText, IF(P29, OKText, ErrorText)) -> BLANK
A30: Additional Comments | J30: Additional Comments
